[toc]





&emsp;
&emsp; 
# 一、基础
## 1. `raise`
### 1.1 `raise`的作用是？
&emsp;&emsp; `raise`，的作用是：**显示地引发异常**。一旦执行了`raise`语句，`raise`后面的语句将不能执行。

### 1.2 什么对象可以被`raise`？
`raise`语法格式为 `raise [Exception [, args [, traceback]]]`，：
```python

    raise 异常类       # 引发异常时会隐式地创建类对象
    raise 异常类对象   # 引发异常类实例对象对应的异常
    raise             # 重新引发刚刚发生的异常
```
`raise` 的参数是可选的：
> &emsp;&emsp; **如果提供参数**，则参数必须是一个异常的实例或者是异常的类（也就是 `Exception` 的子类） 或者是 异常类的实例对象。
> &emsp;&emsp; **如果不提供参数**，则表示重新引发刚刚发生的异常，如果刚刚没有发生异常，则会报错。

### 1.3 `raise`一个异常之后，后面的代码是否还执行？
&emsp;&emsp; 如果`raise`出一个异常后，如果没有将其捕获，那么程序将终止执行，用一段代码来验证一下：
```python
def multi_errors(flag):
    try:
        if(flag == 0):
            raise TypeError("格式异常！")
    except RuntimeError as e:
        print(f"caught {e.__class__.__name__}")
    else:
        print("I'm in else.")

if __name__ == "__main__":
    multi_errors(0)
    print("-"*20)
    multi_errors(1)
    print("程序被顺利执行！")
```
运行结果：
```
Traceback (most recent call last):
  File "d:\code_practice\practice.py", line 11, in <module>
    multi_errors(0)
  File "d:\code_practice\practice.py", line 4, in multi_errors
    raise TypeError("格式异常！")
TypeError: 格式异常！
```
**结果分析：**
&emsp;&emsp; 在`multi_errors(0)`调用中，程序`raise`了`TypeError`异常，但`multi_errors()`函数仅捕获了`RuntimeError`异常，也就是说，程序没有对`TypeError`进行处理，最终程序终止了执行。
&emsp;&emsp; 上面的代码证实了，如果`raise`出来的异常没有被处理，那么程序将终止运行。

### 1.4 `raise`的时候不提供 异常的类型 会发生什么？
&emsp;&emsp; 首先，我们要明白，`raise`的时候不提供 异常的类型 是为了 **再次引发** 刚刚发生的异常：
```python
def handle_erros():
    try: 
        raise RuntimeError
    except:
        print("in except.")
        raise # 此处 再次引发了 刚刚发生的异常，即try里面raise的RuntimeError

if __name__ == "__main__":
    try:
        handle_erros()
    except:
        print("in main.")

    print("successfully accomplish!")
```
运行结果：
```
in except.
in main.
successfully accomplish!
```
**如果刚刚没有发生异常，而程序调用了`raise`，则程序会报错**：
```python
def handle_erros():
    raise 

if __name__ == "__main__":
    handle_erros()
    print("successfully accomplish!")
```
运行结果：
```
Traceback (most recent call last):
  File "d:\code_practice\practice.py", line 6, in <module>
    handle_erros()
  File "d:\code_practice\practice.py", line 2, in handle_erros
    raise
RuntimeError: No active exception to reraise
```

&emsp;
## 2. `try/except...else` 中的else分支将在什么时候运行？
&emsp;&emsp; `try/except` 语句还有一个可选的 `else`子句，如果使用这个子句，那么必须放在所有的 `except`子句之后。else`子句将在 `try`子句没有发生任何异常的时候执行。
```python
def multi_errors(flag):
    try:
        if(flag == 0):
            raise RuntimeError
    except RuntimeError as e:
        print(f"caught {e.__class__.__name__}")
    else:
        print("I'm in else.")

multi_errors(0)
print("-"*20)
multi_errors(1)
```
运行结果：
```
caught RuntimeError
--------------------
I'm in else.
```
**结果分析：**
&emsp;&emsp; 显然，`else`语句中的代码 仅在未发生异常的时候被执行了。

&emsp;
## 3. `try-finally` 
### 3.1 `try-finally` 语句的`finally`什么时候会被调用？
&emsp;&emsp; `finally`语句无论是否发生异常都将执行。
### 3.2 `finally`里面一般用来做什么？
&emsp;&emsp; `finally`一般会会定义一些清理行为，例如关闭文件描述符、断开数据库连接等。


&emsp;
## 4. 如何在`except`子句中获取抛出的异常名？
利用异常的`__class__.__name__`属性即可：
```python
def multi_errors():
    try:
        raise RuntimeError
    except RuntimeError as e:
        print(f"caught {e.__class__.__name__}")

multi_errors()
```
运行结果：
```
caught RuntimeError
```

&emsp;
## 5. 如何在 一个`except`子句中同时处理多个异常？
将你希望捕获的异常放在一个元组中即可：
```python
def multi_errors(flag=2):
    try:
        if(flag == 0):
            raise RuntimeError
        elif(flag == 1):
            raise TypeError
        else:
            raise NameError
    except (RuntimeError, TypeError, NameError) as e:
        print(f"caught {e.__class__.__name__}")

multi_errors(0)
multi_errors(1)
multi_errors()
```
运行结果：
```
caught RuntimeError
caught TypeError
caught NameError
```

&emsp;
## 6. 下面的代码存在什么隐患？
```python
def try_finally_example(filename):
    try:
        print('* Opening file')
        handle = open(filename, encoding='utf-8') # Maybe OSError       
        print('* Reading data')
        return handle.read() # Maybe UnicodeDecodeError
    finally:
        print('* Calling close()')
        handle.close() # Always runs after try block
```  
`open()`语句应该写在`try`语句块的外面，因为假如`open()`文件的时候遇到了错误（例如是文件不存在的`OSError`错误），此时`handle`变量根本来不及得到赋值，从而导致在执行`finally`块时，会因为对无效文件进行`close()`而在读报错。如果把`open()`写在`try`外面就可以在打开文件出错时直接向上抛出异常，从而不进入`finally`语句块。

&emsp;
## 7. 确保无论出现什么异常都可以被处理
### 7.1 如何捕获一个未知错误？
&emsp;&emsp; 在开发时，要预判到所有可能出现的错误，还是有一定难度的，如果希望程序 无论出现任何错误，都不会因为 Python 解释器 抛出异常而被终止，可以在 `except`中不指定任何异常：
```python
# 方式1：
except :
    print("未知错误")

# 方式2（推荐的做法）：
except Exception as result:
    print("未知错误 %s" % result)
```

### 7.2 在实际开发中，如何确保所有异常都可以被处理？
在实际开发中，为了能够处理复杂的异常情况，可以这么写：
```python
try:
    # 尝试执行的代码
    pass
except 错误类型1:
    # 针对错误类型1，对应的代码处理
    pass
except 错误类型2:
    # 针对错误类型2，对应的代码处理
    pass
except (错误类型3, 错误类型4):
    # 针对错误类型3 和 4，对应的代码处理
    pass
except Exception as result:
    # 打印错误信息
    print(result)
else:
    # 没有异常才会执行的代码
    pass
finally:
    # 无论是否有异常，都会执行的代码
    print("无论是否有异常，都会执行的代码")
```

&emsp;
## 8. 异常的传递 和 程序的终止
&emsp;&emsp; 如果不处理函数中引发的异常，它将向上传播到调用函数的地方。如果在那里也未得到处理，异常将继续传播，直至到达主程序（全局作用域）。如果主程序中也没有异常处理程序，程序将终止并显示栈跟踪消息。来看一个示例：
```python
def faulty():
    raise Exception('Something is wrong')

def ignore_exception():
    faulty()

if __name__ == "__main__":
    ignore_exception()
    print("successfully accomplish!")
```
运行结果：
```
Traceback (most recent call last):
  File "d:\code_practice\practice.py", line 8, in <module>
    ignore_exception()
  File "d:\code_practice\practice.py", line 5, in ignore_exception
    faulty()
  File "d:\code_practice\practice.py", line 2, in faulty
    raise Exception('Something is wrong')
Exception: Something is wrong
```
**结果分析：**
&emsp;&emsp; 根据运行结果可知，`faulty()`中`raise`出来的异常，先传到了`ignore_exception()`，最后到达了主程序，主程序中的`print("successfully accomplish!")`没有被执行，说明主程序直接终止了。

&emsp;
## 8. 如果希望 异常发生时执行一段代码，未发生异常时执行另一段代码，应该怎么写？、
使用`try/except/else`即可：
```python

```






&emsp;
&emsp;
&emsp;
# 二、自定义异常
## 1. 如何自定义异常？
&emsp;&emsp; 可以通过创建一个新的异常类来拥有自己的异常。异常类继承自 `Exception`类，可以直接继承，或者间接继承，例如：
```python
class MyError(Exception):
    def __init__(self, value):
        self.value = value
    def __str__(self):
        return repr(self.value)

try:
    raise MyError(2*2)
except MyError as e:
    print('My exception occurred, value:', e.value)
```
运行结果：
```
My exception occurred, value: 4
```
&emsp;&emsp; 当创建一个模块有可能抛出多种不同的异常时，一种通常的做法是为这个包建立一个基础异常类，然后基于这个基础类为不同的错误情况创建不同的子类:
```python
class Error(Exception):
    """Base class for exceptions in this module."""
    pass

class InputError(Error):
    """Exception raised for errors in the input.

    Attributes:
        expression -- input expression in which the error occurred
        message -- explanation of the error
    """

    def __init__(self, expression, message):
        self.expression = expression
        self.message = message

class TransitionError(Error):
    """Raised when an operation attempts a state transition that's not
    allowed.

    Attributes:
        previous -- state at beginning of transition
        next -- attempted new state
        message -- explanation of why the specific transition is not allowed
    """

    def __init__(self, previous, next, message):
        self.previous = previous
        self.next = next
        self.message = message
```

## 2. 自定义异常的命名规则
&emsp;&emsp; 异常的名字一般都以`Error`结尾，就跟标准的异常命名一样。

